2022-04-28 17:44:34,571 ERROR asyncio Task exception was never retrieved
future: <Task finished name='Task-129' coro=<Dispatcher._process_polling_updates() done, defined at C:\Users\Acer\AppData\Local\Programs\Python\Python310\lib\site-packages\aiogram\dispatcher\dispatcher.py:407> exception=OperationalError('no such column: change_photo')>
Traceback (most recent call last):
  File "C:\Users\Acer\AppData\Local\Programs\Python\Python310\lib\site-packages\aiogram\dispatcher\dispatcher.py", line 415, in _process_polling_updates
    for responses in itertools.chain.from_iterable(await self.process_updates(updates, fast)):
  File "C:\Users\Acer\AppData\Local\Programs\Python\Python310\lib\site-packages\aiogram\dispatcher\dispatcher.py", line 235, in process_updates
    return await asyncio.gather(*tasks)
  File "C:\Users\Acer\AppData\Local\Programs\Python\Python310\lib\site-packages\aiogram\dispatcher\handler.py", line 116, in notify
    response = await handler_obj.handler(*args, **partial_data)
  File "C:\Users\Acer\AppData\Local\Programs\Python\Python310\lib\site-packages\aiogram\dispatcher\dispatcher.py", line 283, in process_update
    return await self.callback_query_handlers.notify(update.callback_query)
  File "C:\Users\Acer\AppData\Local\Programs\Python\Python310\lib\site-packages\aiogram\dispatcher\handler.py", line 116, in notify
    response = await handler_obj.handler(*args, **partial_data)
  File "C:\Users\Acer\PycharmProjects\FeDaZa_SCP_Tg_Database\TEST\q2.py", line 108, in callbacks_num
    info = browse(f'{int(num_SCP) + 1}', call.message.chat.id)
  File "C:\Users\Acer\PycharmProjects\FeDaZa_SCP_Tg_Database\utilites.py", line 59, in browse
    cur.execute(f'''UPDATE users SET change_photo = 'False' WHERE userid = {id}''')
sqlite3.OperationalError: no such column: change_photo
