2022-04-24 12:40:26,630 ERROR asyncio Task exception was never retrieved
future: <Task finished name='Task-7' coro=<Dispatcher._process_polling_updates() done, defined at E:\SCP_FOUNDATION\venv\lib\site-packages\aiogram\dispatcher\dispatcher.py:407> exception=OperationalError('11 values for 10 columns')>
Traceback (most recent call last):
  File "E:\SCP_FOUNDATION\venv\lib\site-packages\aiogram\dispatcher\dispatcher.py", line 415, in _process_polling_updates
    for responses in itertools.chain.from_iterable(await self.process_updates(updates, fast)):
  File "E:\SCP_FOUNDATION\venv\lib\site-packages\aiogram\dispatcher\dispatcher.py", line 235, in process_updates
    return await asyncio.gather(*tasks)
  File "E:\SCP_FOUNDATION\venv\lib\site-packages\aiogram\dispatcher\handler.py", line 116, in notify
    response = await handler_obj.handler(*args, **partial_data)
  File "E:\SCP_FOUNDATION\venv\lib\site-packages\aiogram\dispatcher\dispatcher.py", line 256, in process_update
    return await self.message_handlers.notify(update.message)
  File "E:\SCP_FOUNDATION\venv\lib\site-packages\aiogram\dispatcher\handler.py", line 116, in notify
    response = await handler_obj.handler(*args, **partial_data)
  File "E:/SCP_FOUNDATION/FeDaZa_SCP_Tg_Database/main.py", line 51, in send_welcome
    cur.execute(sql, data_tuple)
sqlite3.OperationalError: 11 values for 10 columns
2022-04-24 12:40:43,637 ERROR asyncio Task exception was never retrieved
future: <Task finished name='Task-7' coro=<Dispatcher._process_polling_updates() done, defined at E:\SCP_FOUNDATION\venv\lib\site-packages\aiogram\dispatcher\dispatcher.py:407> exception=OperationalError('11 values for 10 columns')>
Traceback (most recent call last):
  File "E:\SCP_FOUNDATION\venv\lib\site-packages\aiogram\dispatcher\dispatcher.py", line 415, in _process_polling_updates
    for responses in itertools.chain.from_iterable(await self.process_updates(updates, fast)):
  File "E:\SCP_FOUNDATION\venv\lib\site-packages\aiogram\dispatcher\dispatcher.py", line 235, in process_updates
    return await asyncio.gather(*tasks)
  File "E:\SCP_FOUNDATION\venv\lib\site-packages\aiogram\dispatcher\handler.py", line 116, in notify
    response = await handler_obj.handler(*args, **partial_data)
  File "E:\SCP_FOUNDATION\venv\lib\site-packages\aiogram\dispatcher\dispatcher.py", line 256, in process_update
    return await self.message_handlers.notify(update.message)
  File "E:\SCP_FOUNDATION\venv\lib\site-packages\aiogram\dispatcher\handler.py", line 116, in notify
    response = await handler_obj.handler(*args, **partial_data)
  File "E:/SCP_FOUNDATION/FeDaZa_SCP_Tg_Database/main.py", line 51, in send_welcome
    cur.execute(sql, data_tuple)
sqlite3.OperationalError: 11 values for 10 columns
2022-04-24 12:47:47,671 ERROR asyncio Task exception was never retrieved
future: <Task finished name='Task-7' coro=<Dispatcher._process_polling_updates() done, defined at E:\SCP_FOUNDATION\venv\lib\site-packages\aiogram\dispatcher\dispatcher.py:407> exception=OperationalError('no such column: change_photo')>
Traceback (most recent call last):
  File "E:\SCP_FOUNDATION\venv\lib\site-packages\aiogram\dispatcher\dispatcher.py", line 415, in _process_polling_updates
    for responses in itertools.chain.from_iterable(await self.process_updates(updates, fast)):
  File "E:\SCP_FOUNDATION\venv\lib\site-packages\aiogram\dispatcher\dispatcher.py", line 235, in process_updates
    return await asyncio.gather(*tasks)
  File "E:\SCP_FOUNDATION\venv\lib\site-packages\aiogram\dispatcher\handler.py", line 116, in notify
    response = await handler_obj.handler(*args, **partial_data)
  File "E:\SCP_FOUNDATION\venv\lib\site-packages\aiogram\dispatcher\dispatcher.py", line 256, in process_update
    return await self.message_handlers.notify(update.message)
  File "E:\SCP_FOUNDATION\venv\lib\site-packages\aiogram\dispatcher\handler.py", line 116, in notify
    response = await handler_obj.handler(*args, **partial_data)
  File "E:/SCP_FOUNDATION/FeDaZa_SCP_Tg_Database/main.py", line 84, in profile
    cur.execute(f'''UPDATE users SET change_photo = 'False' WHERE userid = {msg.from_user.id}''')
sqlite3.OperationalError: no such column: change_photo
2022-04-24 13:26:57,333 ERROR asyncio Task exception was never retrieved
future: <Task finished name='Task-11' coro=<Dispatcher._process_polling_updates() done, defined at E:\SCP_FOUNDATION\venv\lib\site-packages\aiogram\dispatcher\dispatcher.py:407> exception=KeyError(0)>
Traceback (most recent call last):
  File "E:\SCP_FOUNDATION\venv\lib\site-packages\aiogram\dispatcher\dispatcher.py", line 415, in _process_polling_updates
    for responses in itertools.chain.from_iterable(await self.process_updates(updates, fast)):
  File "E:\SCP_FOUNDATION\venv\lib\site-packages\aiogram\dispatcher\dispatcher.py", line 235, in process_updates
    return await asyncio.gather(*tasks)
  File "E:\SCP_FOUNDATION\venv\lib\site-packages\aiogram\dispatcher\handler.py", line 116, in notify
    response = await handler_obj.handler(*args, **partial_data)
  File "E:\SCP_FOUNDATION\venv\lib\site-packages\aiogram\dispatcher\dispatcher.py", line 256, in process_update
    return await self.message_handlers.notify(update.message)
  File "E:\SCP_FOUNDATION\venv\lib\site-packages\aiogram\dispatcher\handler.py", line 116, in notify
    response = await handler_obj.handler(*args, **partial_data)
  File "E:/SCP_FOUNDATION/FeDaZa_SCP_Tg_Database/main.py", line 113, in profile
    await bot.send_photo(msg.chat.id, str(profile[0][7]))  # Вывод фото профиля и его статистики
KeyError: 0
2022-04-24 13:28:20,256 ERROR root 855707706 kurakura222 tuple indices must be integers or slices, not str
2022-04-24 13:29:22,359 ERROR root 855707706 kurakura222 tuple indices must be integers or slices, not str
2022-04-24 13:29:56,692 ERROR root 855707706 kurakura222 tuple indices must be integers or slices, not str
2022-04-24 13:31:11,361 ERROR asyncio Task exception was never retrieved
future: <Task finished name='Task-7' coro=<Dispatcher._process_polling_updates() done, defined at E:\SCP_FOUNDATION\venv\lib\site-packages\aiogram\dispatcher\dispatcher.py:407> exception=UnboundLocalError("local variable 'browse' referenced before assignment")>
Traceback (most recent call last):
  File "E:\SCP_FOUNDATION\venv\lib\site-packages\aiogram\dispatcher\dispatcher.py", line 415, in _process_polling_updates
    for responses in itertools.chain.from_iterable(await self.process_updates(updates, fast)):
  File "E:\SCP_FOUNDATION\venv\lib\site-packages\aiogram\dispatcher\dispatcher.py", line 235, in process_updates
    return await asyncio.gather(*tasks)
  File "E:\SCP_FOUNDATION\venv\lib\site-packages\aiogram\dispatcher\handler.py", line 116, in notify
    response = await handler_obj.handler(*args, **partial_data)
  File "E:\SCP_FOUNDATION\venv\lib\site-packages\aiogram\dispatcher\dispatcher.py", line 256, in process_update
    return await self.message_handlers.notify(update.message)
  File "E:\SCP_FOUNDATION\venv\lib\site-packages\aiogram\dispatcher\handler.py", line 116, in notify
    response = await handler_obj.handler(*args, **partial_data)
  File "E:/SCP_FOUNDATION/FeDaZa_SCP_Tg_Database/main.py", line 168, in browse
    print(browse[language])
UnboundLocalError: local variable 'browse' referenced before assignment
2022-04-24 13:31:27,928 ERROR asyncio Task exception was never retrieved
future: <Task finished name='Task-7' coro=<Dispatcher._process_polling_updates() done, defined at E:\SCP_FOUNDATION\venv\lib\site-packages\aiogram\dispatcher\dispatcher.py:407> exception=UnboundLocalError("local variable 'browse' referenced before assignment")>
Traceback (most recent call last):
  File "E:\SCP_FOUNDATION\venv\lib\site-packages\aiogram\dispatcher\dispatcher.py", line 415, in _process_polling_updates
    for responses in itertools.chain.from_iterable(await self.process_updates(updates, fast)):
  File "E:\SCP_FOUNDATION\venv\lib\site-packages\aiogram\dispatcher\dispatcher.py", line 235, in process_updates
    return await asyncio.gather(*tasks)
  File "E:\SCP_FOUNDATION\venv\lib\site-packages\aiogram\dispatcher\handler.py", line 116, in notify
    response = await handler_obj.handler(*args, **partial_data)
  File "E:\SCP_FOUNDATION\venv\lib\site-packages\aiogram\dispatcher\dispatcher.py", line 256, in process_update
    return await self.message_handlers.notify(update.message)
  File "E:\SCP_FOUNDATION\venv\lib\site-packages\aiogram\dispatcher\handler.py", line 116, in notify
    response = await handler_obj.handler(*args, **partial_data)
  File "E:/SCP_FOUNDATION/FeDaZa_SCP_Tg_Database/main.py", line 168, in browse
    print(browse[language])
UnboundLocalError: local variable 'browse' referenced before assignment
2022-04-24 13:32:01,478 ERROR asyncio Task exception was never retrieved
future: <Task finished name='Task-13' coro=<Dispatcher._process_polling_updates() done, defined at E:\SCP_FOUNDATION\venv\lib\site-packages\aiogram\dispatcher\dispatcher.py:407> exception=NameError("name 'language_text' is not defined")>
Traceback (most recent call last):
  File "E:\SCP_FOUNDATION\venv\lib\site-packages\aiogram\dispatcher\dispatcher.py", line 415, in _process_polling_updates
    for responses in itertools.chain.from_iterable(await self.process_updates(updates, fast)):
  File "E:\SCP_FOUNDATION\venv\lib\site-packages\aiogram\dispatcher\dispatcher.py", line 235, in process_updates
    return await asyncio.gather(*tasks)
  File "E:\SCP_FOUNDATION\venv\lib\site-packages\aiogram\dispatcher\handler.py", line 116, in notify
    response = await handler_obj.handler(*args, **partial_data)
  File "E:\SCP_FOUNDATION\venv\lib\site-packages\aiogram\dispatcher\dispatcher.py", line 256, in process_update
    return await self.message_handlers.notify(update.message)
  File "E:\SCP_FOUNDATION\venv\lib\site-packages\aiogram\dispatcher\handler.py", line 116, in notify
    response = await handler_obj.handler(*args, **partial_data)
  File "E:/SCP_FOUNDATION/FeDaZa_SCP_Tg_Database/main.py", line 83, in helper
    await msg.reply(language_text['help'][language])
NameError: name 'language_text' is not defined
2022-04-24 13:34:47,326 ERROR asyncio Task exception was never retrieved
future: <Task finished name='Task-7' coro=<Dispatcher._process_polling_updates() done, defined at E:\SCP_FOUNDATION\venv\lib\site-packages\aiogram\dispatcher\dispatcher.py:407> exception=NameError("name 'language_text' is not defined")>
Traceback (most recent call last):
  File "E:\SCP_FOUNDATION\venv\lib\site-packages\aiogram\dispatcher\dispatcher.py", line 415, in _process_polling_updates
    for responses in itertools.chain.from_iterable(await self.process_updates(updates, fast)):
  File "E:\SCP_FOUNDATION\venv\lib\site-packages\aiogram\dispatcher\dispatcher.py", line 235, in process_updates
    return await asyncio.gather(*tasks)
  File "E:\SCP_FOUNDATION\venv\lib\site-packages\aiogram\dispatcher\handler.py", line 116, in notify
    response = await handler_obj.handler(*args, **partial_data)
  File "E:\SCP_FOUNDATION\venv\lib\site-packages\aiogram\dispatcher\dispatcher.py", line 256, in process_update
    return await self.message_handlers.notify(update.message)
  File "E:\SCP_FOUNDATION\venv\lib\site-packages\aiogram\dispatcher\handler.py", line 116, in notify
    response = await handler_obj.handler(*args, **partial_data)
  File "E:/SCP_FOUNDATION/FeDaZa_SCP_Tg_Database/main.py", line 83, in helper
    await msg.reply(language_text['help'][language])
NameError: name 'language_text' is not defined
2022-04-24 22:01:32,157 ERROR aiogram.dispatcher.dispatcher Cause exception while getting updates.
Traceback (most recent call last):
  File "C:\Users\Acer\AppData\Local\Programs\Python\Python310\lib\site-packages\aiogram\dispatcher\dispatcher.py", line 381, in start_polling
    updates = await self.bot.get_updates(
  File "C:\Users\Acer\AppData\Local\Programs\Python\Python310\lib\site-packages\aiogram\bot\bot.py", line 110, in get_updates
    result = await self.request(api.Methods.GET_UPDATES, payload)
  File "C:\Users\Acer\AppData\Local\Programs\Python\Python310\lib\site-packages\aiogram\bot\base.py", line 231, in request
    return await api.make_request(await self.get_session(), self.server, self.__token, method, data, files,
  File "C:\Users\Acer\AppData\Local\Programs\Python\Python310\lib\site-packages\aiogram\bot\api.py", line 140, in make_request
    return check_result(method, response.content_type, response.status, await response.text())
  File "C:\Users\Acer\AppData\Local\Programs\Python\Python310\lib\site-packages\aiogram\bot\api.py", line 119, in check_result
    exceptions.ConflictError.detect(description)
  File "C:\Users\Acer\AppData\Local\Programs\Python\Python310\lib\site-packages\aiogram\utils\exceptions.py", line 140, in detect
    raise err(cls.text or description)
aiogram.utils.exceptions.TerminatedByOtherGetUpdates: Terminated by other getupdates request; make sure that only one bot instance is running
2022-04-24 22:03:39,991 ERROR root 971934495 vardabomb 'NoneType' object has no attribute 'text'
2022-04-24 22:03:57,737 ERROR root 971934495 vardabomb 'NoneType' object has no attribute 'text'
2022-04-24 22:04:52,440 ERROR asyncio Task exception was never retrieved
future: <Task finished name='Task-96' coro=<Dispatcher._process_polling_updates() done, defined at C:\Users\Acer\AppData\Local\Programs\Python\Python310\lib\site-packages\aiogram\dispatcher\dispatcher.py:407> exception=TypeError("Message.answer() missing 1 required positional argument: 'text'")>
Traceback (most recent call last):
  File "C:\Users\Acer\AppData\Local\Programs\Python\Python310\lib\site-packages\aiogram\dispatcher\dispatcher.py", line 415, in _process_polling_updates
    for responses in itertools.chain.from_iterable(await self.process_updates(updates, fast)):
  File "C:\Users\Acer\AppData\Local\Programs\Python\Python310\lib\site-packages\aiogram\dispatcher\dispatcher.py", line 235, in process_updates
    return await asyncio.gather(*tasks)
  File "C:\Users\Acer\AppData\Local\Programs\Python\Python310\lib\site-packages\aiogram\dispatcher\handler.py", line 116, in notify
    response = await handler_obj.handler(*args, **partial_data)
  File "C:\Users\Acer\AppData\Local\Programs\Python\Python310\lib\site-packages\aiogram\dispatcher\dispatcher.py", line 283, in process_update
    return await self.callback_query_handlers.notify(update.callback_query)
  File "C:\Users\Acer\AppData\Local\Programs\Python\Python310\lib\site-packages\aiogram\dispatcher\handler.py", line 116, in notify
    response = await handler_obj.handler(*args, **partial_data)
  File "C:\Users\Acer\PycharmProjects\FeDaZa_SCP_Tg_Database\q2.py", line 78, in callbacks_num
    await call.message.answer(reply_markup=markup_menu)
TypeError: Message.answer() missing 1 required positional argument: 'text'
2022-04-24 23:25:12,825 ERROR root unsupported operand type(s) for +: 'NoneType' and 'list'
2022-04-24 23:25:12,825 ERROR asyncio Task exception was never retrieved
future: <Task finished name='Task-33' coro=<Dispatcher._process_polling_updates() done, defined at C:\Users\Acer\AppData\Local\Programs\Python\Python310\lib\site-packages\aiogram\dispatcher\dispatcher.py:407> exception=OperationalError('near ")": syntax error')>
Traceback (most recent call last):
  File "C:\Users\Acer\PycharmProjects\FeDaZa_SCP_Tg_Database\utilites.py", line 75, in browse
    retur['text'] = retur['text'] + [info[x:x + 4096]]
TypeError: unsupported operand type(s) for +: 'NoneType' and 'list'

During handling of the above exception, another exception occurred:

Traceback (most recent call last):
  File "C:\Users\Acer\AppData\Local\Programs\Python\Python310\lib\site-packages\aiogram\dispatcher\dispatcher.py", line 415, in _process_polling_updates
    for responses in itertools.chain.from_iterable(await self.process_updates(updates, fast)):
  File "C:\Users\Acer\AppData\Local\Programs\Python\Python310\lib\site-packages\aiogram\dispatcher\dispatcher.py", line 235, in process_updates
    return await asyncio.gather(*tasks)
  File "C:\Users\Acer\AppData\Local\Programs\Python\Python310\lib\site-packages\aiogram\dispatcher\handler.py", line 116, in notify
    response = await handler_obj.handler(*args, **partial_data)
  File "C:\Users\Acer\AppData\Local\Programs\Python\Python310\lib\site-packages\aiogram\dispatcher\dispatcher.py", line 283, in process_update
    return await self.callback_query_handlers.notify(update.callback_query)
  File "C:\Users\Acer\AppData\Local\Programs\Python\Python310\lib\site-packages\aiogram\dispatcher\handler.py", line 116, in notify
    response = await handler_obj.handler(*args, **partial_data)
  File "C:\Users\Acer\PycharmProjects\FeDaZa_SCP_Tg_Database\q2.py", line 72, in callbacks_num
    info = browse(num_SCP, call.message.chat.id)
  File "C:\Users\Acer\PycharmProjects\FeDaZa_SCP_Tg_Database\utilites.py", line 82, in browse
    cur.execute(  # Фиксирование ошибки и прикрепление ошибки к пользователю, для возможного опроса в будущем
sqlite3.OperationalError: near ")": syntax error
2022-04-24 23:26:25,014 ERROR asyncio Task exception was never retrieved
future: <Task finished name='Task-37' coro=<Dispatcher._process_polling_updates() done, defined at C:\Users\Acer\AppData\Local\Programs\Python\Python310\lib\site-packages\aiogram\dispatcher\dispatcher.py:407> exception=TypeError("Message.answer() missing 1 required positional argument: 'text'")>
Traceback (most recent call last):
  File "C:\Users\Acer\AppData\Local\Programs\Python\Python310\lib\site-packages\aiogram\dispatcher\dispatcher.py", line 415, in _process_polling_updates
    for responses in itertools.chain.from_iterable(await self.process_updates(updates, fast)):
  File "C:\Users\Acer\AppData\Local\Programs\Python\Python310\lib\site-packages\aiogram\dispatcher\dispatcher.py", line 235, in process_updates
    return await asyncio.gather(*tasks)
  File "C:\Users\Acer\AppData\Local\Programs\Python\Python310\lib\site-packages\aiogram\dispatcher\handler.py", line 116, in notify
    response = await handler_obj.handler(*args, **partial_data)
  File "C:\Users\Acer\AppData\Local\Programs\Python\Python310\lib\site-packages\aiogram\dispatcher\dispatcher.py", line 283, in process_update
    return await self.callback_query_handlers.notify(update.callback_query)
  File "C:\Users\Acer\AppData\Local\Programs\Python\Python310\lib\site-packages\aiogram\dispatcher\handler.py", line 116, in notify
    response = await handler_obj.handler(*args, **partial_data)
  File "C:\Users\Acer\PycharmProjects\FeDaZa_SCP_Tg_Database\q2.py", line 80, in callbacks_num
    await call.message.answer(reply_markup=markup_menu)
TypeError: Message.answer() missing 1 required positional argument: 'text'
2022-04-24 23:27:05,859 ERROR root unsupported operand type(s) for +: 'NoneType' and 'list'
2022-04-24 23:27:05,859 ERROR asyncio Task exception was never retrieved
future: <Task finished name='Task-33' coro=<Dispatcher._process_polling_updates() done, defined at C:\Users\Acer\AppData\Local\Programs\Python\Python310\lib\site-packages\aiogram\dispatcher\dispatcher.py:407> exception=OperationalError('near ")": syntax error')>
Traceback (most recent call last):
  File "C:\Users\Acer\PycharmProjects\FeDaZa_SCP_Tg_Database\utilites.py", line 75, in browse
    retur['text'] = retur['text'] + [info[x:x + 4096]]
TypeError: unsupported operand type(s) for +: 'NoneType' and 'list'

During handling of the above exception, another exception occurred:

Traceback (most recent call last):
  File "C:\Users\Acer\AppData\Local\Programs\Python\Python310\lib\site-packages\aiogram\dispatcher\dispatcher.py", line 415, in _process_polling_updates
    for responses in itertools.chain.from_iterable(await self.process_updates(updates, fast)):
  File "C:\Users\Acer\AppData\Local\Programs\Python\Python310\lib\site-packages\aiogram\dispatcher\dispatcher.py", line 235, in process_updates
    return await asyncio.gather(*tasks)
  File "C:\Users\Acer\AppData\Local\Programs\Python\Python310\lib\site-packages\aiogram\dispatcher\handler.py", line 116, in notify
    response = await handler_obj.handler(*args, **partial_data)
  File "C:\Users\Acer\AppData\Local\Programs\Python\Python310\lib\site-packages\aiogram\dispatcher\dispatcher.py", line 283, in process_update
    return await self.callback_query_handlers.notify(update.callback_query)
  File "C:\Users\Acer\AppData\Local\Programs\Python\Python310\lib\site-packages\aiogram\dispatcher\handler.py", line 116, in notify
    response = await handler_obj.handler(*args, **partial_data)
  File "C:\Users\Acer\PycharmProjects\FeDaZa_SCP_Tg_Database\q2.py", line 72, in callbacks_num
    info = browse(num_SCP, call.message.chat.id)
  File "C:\Users\Acer\PycharmProjects\FeDaZa_SCP_Tg_Database\utilites.py", line 82, in browse
    cur.execute(  # Фиксирование ошибки и прикрепление ошибки к пользователю, для возможного опроса в будущем
sqlite3.OperationalError: near ")": syntax error
2022-04-24 23:31:04,826 ERROR root 971934495 vardabomb database is locked
2022-04-24 23:31:10,345 ERROR asyncio Task exception was never retrieved
future: <Task finished name='Task-38' coro=<Dispatcher._process_polling_updates() done, defined at C:\Users\Acer\AppData\Local\Programs\Python\Python310\lib\site-packages\aiogram\dispatcher\dispatcher.py:407> exception=OperationalError('database is locked')>
Traceback (most recent call last):
  File "C:\Users\Acer\PycharmProjects\FeDaZa_SCP_Tg_Database\q2.py", line 211, in with_puree
    cur.execute(
sqlite3.OperationalError: database is locked

During handling of the above exception, another exception occurred:

Traceback (most recent call last):
  File "C:\Users\Acer\AppData\Local\Programs\Python\Python310\lib\site-packages\aiogram\dispatcher\dispatcher.py", line 415, in _process_polling_updates
    for responses in itertools.chain.from_iterable(await self.process_updates(updates, fast)):
  File "C:\Users\Acer\AppData\Local\Programs\Python\Python310\lib\site-packages\aiogram\dispatcher\dispatcher.py", line 235, in process_updates
    return await asyncio.gather(*tasks)
  File "C:\Users\Acer\AppData\Local\Programs\Python\Python310\lib\site-packages\aiogram\dispatcher\handler.py", line 116, in notify
    response = await handler_obj.handler(*args, **partial_data)
  File "C:\Users\Acer\AppData\Local\Programs\Python\Python310\lib\site-packages\aiogram\dispatcher\dispatcher.py", line 256, in process_update
    return await self.message_handlers.notify(update.message)
  File "C:\Users\Acer\AppData\Local\Programs\Python\Python310\lib\site-packages\aiogram\dispatcher\handler.py", line 116, in notify
    response = await handler_obj.handler(*args, **partial_data)
  File "C:\Users\Acer\PycharmProjects\FeDaZa_SCP_Tg_Database\q2.py", line 240, in with_puree
    cur.execute(  # Фиксирование ошибки и прикрепление ошибки к пользователю, для возможного опроса в будущем
sqlite3.OperationalError: database is locked
2022-04-24 23:31:14,002 ERROR root unsupported operand type(s) for +: 'NoneType' and 'list'
2022-04-24 23:31:14,002 ERROR asyncio Task exception was never retrieved
future: <Task finished name='Task-48' coro=<Dispatcher._process_polling_updates() done, defined at C:\Users\Acer\AppData\Local\Programs\Python\Python310\lib\site-packages\aiogram\dispatcher\dispatcher.py:407> exception=OperationalError('near ")": syntax error')>
Traceback (most recent call last):
  File "C:\Users\Acer\PycharmProjects\FeDaZa_SCP_Tg_Database\utilites.py", line 75, in browse
    retur['text'] = retur['text'] + [info[x:x + 4096]]
TypeError: unsupported operand type(s) for +: 'NoneType' and 'list'

During handling of the above exception, another exception occurred:

Traceback (most recent call last):
  File "C:\Users\Acer\AppData\Local\Programs\Python\Python310\lib\site-packages\aiogram\dispatcher\dispatcher.py", line 415, in _process_polling_updates
    for responses in itertools.chain.from_iterable(await self.process_updates(updates, fast)):
  File "C:\Users\Acer\AppData\Local\Programs\Python\Python310\lib\site-packages\aiogram\dispatcher\dispatcher.py", line 235, in process_updates
    return await asyncio.gather(*tasks)
  File "C:\Users\Acer\AppData\Local\Programs\Python\Python310\lib\site-packages\aiogram\dispatcher\handler.py", line 116, in notify
    response = await handler_obj.handler(*args, **partial_data)
  File "C:\Users\Acer\AppData\Local\Programs\Python\Python310\lib\site-packages\aiogram\dispatcher\dispatcher.py", line 283, in process_update
    return await self.callback_query_handlers.notify(update.callback_query)
  File "C:\Users\Acer\AppData\Local\Programs\Python\Python310\lib\site-packages\aiogram\dispatcher\handler.py", line 116, in notify
    response = await handler_obj.handler(*args, **partial_data)
  File "C:\Users\Acer\PycharmProjects\FeDaZa_SCP_Tg_Database\q2.py", line 72, in callbacks_num
    info = browse(num_SCP, call.message.chat.id)
  File "C:\Users\Acer\PycharmProjects\FeDaZa_SCP_Tg_Database\utilites.py", line 82, in browse
    cur.execute(  # Фиксирование ошибки и прикрепление ошибки к пользователю, для возможного опроса в будущем
sqlite3.OperationalError: near ")": syntax error
2022-04-24 23:35:56,928 ERROR root unsupported operand type(s) for +: 'NoneType' and 'list'
2022-04-24 23:35:56,928 ERROR asyncio Task exception was never retrieved
future: <Task finished name='Task-29' coro=<Dispatcher._process_polling_updates() done, defined at C:\Users\Acer\AppData\Local\Programs\Python\Python310\lib\site-packages\aiogram\dispatcher\dispatcher.py:407> exception=OperationalError('near ")": syntax error')>
Traceback (most recent call last):
  File "C:\Users\Acer\PycharmProjects\FeDaZa_SCP_Tg_Database\utilites.py", line 75, in browse
    retur['text'] = retur['text'] + [info[x:x + 4096]]
TypeError: unsupported operand type(s) for +: 'NoneType' and 'list'

During handling of the above exception, another exception occurred:

Traceback (most recent call last):
  File "C:\Users\Acer\AppData\Local\Programs\Python\Python310\lib\site-packages\aiogram\dispatcher\dispatcher.py", line 415, in _process_polling_updates
    for responses in itertools.chain.from_iterable(await self.process_updates(updates, fast)):
  File "C:\Users\Acer\AppData\Local\Programs\Python\Python310\lib\site-packages\aiogram\dispatcher\dispatcher.py", line 235, in process_updates
    return await asyncio.gather(*tasks)
  File "C:\Users\Acer\AppData\Local\Programs\Python\Python310\lib\site-packages\aiogram\dispatcher\handler.py", line 116, in notify
    response = await handler_obj.handler(*args, **partial_data)
  File "C:\Users\Acer\AppData\Local\Programs\Python\Python310\lib\site-packages\aiogram\dispatcher\dispatcher.py", line 283, in process_update
    return await self.callback_query_handlers.notify(update.callback_query)
  File "C:\Users\Acer\AppData\Local\Programs\Python\Python310\lib\site-packages\aiogram\dispatcher\handler.py", line 116, in notify
    response = await handler_obj.handler(*args, **partial_data)
  File "C:\Users\Acer\PycharmProjects\FeDaZa_SCP_Tg_Database\q2.py", line 72, in callbacks_num
    info = browse(num_SCP, call.message.chat.id)
  File "C:\Users\Acer\PycharmProjects\FeDaZa_SCP_Tg_Database\utilites.py", line 82, in browse
    cur.execute(  # Фиксирование ошибки и прикрепление ошибки к пользователю, для возможного опроса в будущем
sqlite3.OperationalError: near ")": syntax error
2022-04-24 23:44:00,271 ERROR asyncio Task exception was never retrieved
future: <Task finished name='Task-29' coro=<Dispatcher._process_polling_updates() done, defined at C:\Users\Acer\AppData\Local\Programs\Python\Python310\lib\site-packages\aiogram\dispatcher\dispatcher.py:407> exception=TypeError("'list' object cannot be interpreted as an integer")>
Traceback (most recent call last):
  File "C:\Users\Acer\AppData\Local\Programs\Python\Python310\lib\site-packages\aiogram\dispatcher\dispatcher.py", line 415, in _process_polling_updates
    for responses in itertools.chain.from_iterable(await self.process_updates(updates, fast)):
  File "C:\Users\Acer\AppData\Local\Programs\Python\Python310\lib\site-packages\aiogram\dispatcher\dispatcher.py", line 235, in process_updates
    return await asyncio.gather(*tasks)
  File "C:\Users\Acer\AppData\Local\Programs\Python\Python310\lib\site-packages\aiogram\dispatcher\handler.py", line 116, in notify
    response = await handler_obj.handler(*args, **partial_data)
  File "C:\Users\Acer\AppData\Local\Programs\Python\Python310\lib\site-packages\aiogram\dispatcher\dispatcher.py", line 283, in process_update
    return await self.callback_query_handlers.notify(update.callback_query)
  File "C:\Users\Acer\AppData\Local\Programs\Python\Python310\lib\site-packages\aiogram\dispatcher\handler.py", line 116, in notify
    response = await handler_obj.handler(*args, **partial_data)
  File "C:\Users\Acer\PycharmProjects\FeDaZa_SCP_Tg_Database\q2.py", line 75, in callbacks_num
    for x in range(0, info['text'], 4096):
TypeError: 'list' object cannot be interpreted as an integer
2022-04-24 23:46:43,843 ERROR asyncio Task exception was never retrieved
future: <Task finished name='Task-27' coro=<Dispatcher._process_polling_updates() done, defined at C:\Users\Acer\AppData\Local\Programs\Python\Python310\lib\site-packages\aiogram\dispatcher\dispatcher.py:407> exception=TypeError("'str' object cannot be interpreted as an integer")>
Traceback (most recent call last):
  File "C:\Users\Acer\AppData\Local\Programs\Python\Python310\lib\site-packages\aiogram\dispatcher\dispatcher.py", line 415, in _process_polling_updates
    for responses in itertools.chain.from_iterable(await self.process_updates(updates, fast)):
  File "C:\Users\Acer\AppData\Local\Programs\Python\Python310\lib\site-packages\aiogram\dispatcher\dispatcher.py", line 235, in process_updates
    return await asyncio.gather(*tasks)
  File "C:\Users\Acer\AppData\Local\Programs\Python\Python310\lib\site-packages\aiogram\dispatcher\handler.py", line 116, in notify
    response = await handler_obj.handler(*args, **partial_data)
  File "C:\Users\Acer\AppData\Local\Programs\Python\Python310\lib\site-packages\aiogram\dispatcher\dispatcher.py", line 283, in process_update
    return await self.callback_query_handlers.notify(update.callback_query)
  File "C:\Users\Acer\AppData\Local\Programs\Python\Python310\lib\site-packages\aiogram\dispatcher\handler.py", line 116, in notify
    response = await handler_obj.handler(*args, **partial_data)
  File "C:\Users\Acer\PycharmProjects\FeDaZa_SCP_Tg_Database\q2.py", line 75, in callbacks_num
    for x in range(0, info['text'], 4096):
TypeError: 'str' object cannot be interpreted as an integer
2022-04-24 23:48:34,484 ERROR root 971934495 vardabomb database is locked
2022-04-24 23:48:40,026 ERROR asyncio Task exception was never retrieved
future: <Task finished name='Task-41' coro=<Dispatcher._process_polling_updates() done, defined at C:\Users\Acer\AppData\Local\Programs\Python\Python310\lib\site-packages\aiogram\dispatcher\dispatcher.py:407> exception=OperationalError('database is locked')>
Traceback (most recent call last):
  File "C:\Users\Acer\PycharmProjects\FeDaZa_SCP_Tg_Database\q2.py", line 211, in with_puree
    cur.execute(
sqlite3.OperationalError: database is locked

During handling of the above exception, another exception occurred:

Traceback (most recent call last):
  File "C:\Users\Acer\AppData\Local\Programs\Python\Python310\lib\site-packages\aiogram\dispatcher\dispatcher.py", line 415, in _process_polling_updates
    for responses in itertools.chain.from_iterable(await self.process_updates(updates, fast)):
  File "C:\Users\Acer\AppData\Local\Programs\Python\Python310\lib\site-packages\aiogram\dispatcher\dispatcher.py", line 235, in process_updates
    return await asyncio.gather(*tasks)
  File "C:\Users\Acer\AppData\Local\Programs\Python\Python310\lib\site-packages\aiogram\dispatcher\handler.py", line 116, in notify
    response = await handler_obj.handler(*args, **partial_data)
  File "C:\Users\Acer\AppData\Local\Programs\Python\Python310\lib\site-packages\aiogram\dispatcher\dispatcher.py", line 256, in process_update
    return await self.message_handlers.notify(update.message)
  File "C:\Users\Acer\AppData\Local\Programs\Python\Python310\lib\site-packages\aiogram\dispatcher\handler.py", line 116, in notify
    response = await handler_obj.handler(*args, **partial_data)
  File "C:\Users\Acer\PycharmProjects\FeDaZa_SCP_Tg_Database\q2.py", line 240, in with_puree
    cur.execute(  # Фиксирование ошибки и прикрепление ошибки к пользователю, для возможного опроса в будущем
sqlite3.OperationalError: database is locked
2022-04-24 23:53:02,577 ERROR root 971934495 vardabomb no such table: users
2022-04-24 23:53:02,578 ERROR asyncio Task exception was never retrieved
future: <Task finished name='Task-20' coro=<Dispatcher._process_polling_updates() done, defined at C:\Users\Acer\AppData\Local\Programs\Python\Python310\lib\site-packages\aiogram\dispatcher\dispatcher.py:407> exception=OperationalError('no such table: users')>
Traceback (most recent call last):
  File "C:\Users\Acer\PycharmProjects\FeDaZa_SCP_Tg_Database\TEST\q2.py", line 215, in with_puree
    cur.execute(
sqlite3.OperationalError: no such table: users

During handling of the above exception, another exception occurred:

Traceback (most recent call last):
  File "C:\Users\Acer\AppData\Local\Programs\Python\Python310\lib\site-packages\aiogram\dispatcher\dispatcher.py", line 415, in _process_polling_updates
    for responses in itertools.chain.from_iterable(await self.process_updates(updates, fast)):
  File "C:\Users\Acer\AppData\Local\Programs\Python\Python310\lib\site-packages\aiogram\dispatcher\dispatcher.py", line 235, in process_updates
    return await asyncio.gather(*tasks)
  File "C:\Users\Acer\AppData\Local\Programs\Python\Python310\lib\site-packages\aiogram\dispatcher\handler.py", line 116, in notify
    response = await handler_obj.handler(*args, **partial_data)
  File "C:\Users\Acer\AppData\Local\Programs\Python\Python310\lib\site-packages\aiogram\dispatcher\dispatcher.py", line 256, in process_update
    return await self.message_handlers.notify(update.message)
  File "C:\Users\Acer\AppData\Local\Programs\Python\Python310\lib\site-packages\aiogram\dispatcher\handler.py", line 116, in notify
    response = await handler_obj.handler(*args, **partial_data)
  File "C:\Users\Acer\PycharmProjects\FeDaZa_SCP_Tg_Database\TEST\q2.py", line 244, in with_puree
    cur.execute(  # Фиксирование ошибки и прикрепление ошибки к пользователю, для возможного опроса в будущем
sqlite3.OperationalError: no such table: users
2022-04-25 00:09:37,459 ERROR asyncio Task exception was never retrieved
future: <Task finished name='Task-12' coro=<Dispatcher._process_polling_updates() done, defined at C:\Users\Zakhar_M\AppData\Local\Programs\Python\Python38-32\lib\site-packages\aiogram\dispatcher\dispatcher.py:407> exception=IndexError('list index out of range')>
Traceback (most recent call last):
  File "C:\Users\Zakhar_M\AppData\Local\Programs\Python\Python38-32\lib\site-packages\aiogram\dispatcher\dispatcher.py", line 415, in _process_polling_updates
    for responses in itertools.chain.from_iterable(await self.process_updates(updates, fast)):
  File "C:\Users\Zakhar_M\AppData\Local\Programs\Python\Python38-32\lib\site-packages\aiogram\dispatcher\dispatcher.py", line 235, in process_updates
    return await asyncio.gather(*tasks)
  File "C:\Users\Zakhar_M\AppData\Local\Programs\Python\Python38-32\lib\site-packages\aiogram\dispatcher\handler.py", line 116, in notify
    response = await handler_obj.handler(*args, **partial_data)
  File "C:\Users\Zakhar_M\AppData\Local\Programs\Python\Python38-32\lib\site-packages\aiogram\dispatcher\dispatcher.py", line 256, in process_update
    return await self.message_handlers.notify(update.message)
  File "C:\Users\Zakhar_M\AppData\Local\Programs\Python\Python38-32\lib\site-packages\aiogram\dispatcher\handler.py", line 116, in notify
    response = await handler_obj.handler(*args, **partial_data)
  File "F:/Zakhar/Python/FFFFFFFFFFFFFFF/FeDaZa_SCP_Tg_Database/q2.py", line 164, in with_puree
    await bot.send_photo(msg.chat.id, str(profile[0][7]))
IndexError: list index out of range
2022-04-25 00:10:23,659 ERROR root None
2022-04-25 00:10:23,660 ERROR asyncio Task exception was never retrieved
future: <Task finished name='Task-70' coro=<Dispatcher._process_polling_updates() done, defined at C:\Users\Zakhar_M\AppData\Local\Programs\Python\Python38-32\lib\site-packages\aiogram\dispatcher\dispatcher.py:407> exception=OperationalError('near ")": syntax error')>
Traceback (most recent call last):
  File "F:\Zakhar\Python\FFFFFFFFFFFFFFF\FeDaZa_SCP_Tg_Database\utilites.py", line 59, in browse
    print(browse[language])
KeyError: None

During handling of the above exception, another exception occurred:

Traceback (most recent call last):
  File "C:\Users\Zakhar_M\AppData\Local\Programs\Python\Python38-32\lib\site-packages\aiogram\dispatcher\dispatcher.py", line 415, in _process_polling_updates
    for responses in itertools.chain.from_iterable(await self.process_updates(updates, fast)):
  File "C:\Users\Zakhar_M\AppData\Local\Programs\Python\Python38-32\lib\site-packages\aiogram\dispatcher\dispatcher.py", line 235, in process_updates
    return await asyncio.gather(*tasks)
  File "C:\Users\Zakhar_M\AppData\Local\Programs\Python\Python38-32\lib\site-packages\aiogram\dispatcher\handler.py", line 116, in notify
    response = await handler_obj.handler(*args, **partial_data)
  File "C:\Users\Zakhar_M\AppData\Local\Programs\Python\Python38-32\lib\site-packages\aiogram\dispatcher\dispatcher.py", line 283, in process_update
    return await self.callback_query_handlers.notify(update.callback_query)
  File "C:\Users\Zakhar_M\AppData\Local\Programs\Python\Python38-32\lib\site-packages\aiogram\dispatcher\handler.py", line 116, in notify
    response = await handler_obj.handler(*args, **partial_data)
  File "F:/Zakhar/Python/FFFFFFFFFFFFFFF/FeDaZa_SCP_Tg_Database/q2.py", line 72, in callbacks_num
    info = browse(f'{int(num_SCP) + 1}', call.message.chat.id)
  File "F:\Zakhar\Python\FFFFFFFFFFFFFFF\FeDaZa_SCP_Tg_Database\utilites.py", line 78, in browse
    cur.execute(  # Фиксирование ошибки и прикрепление ошибки к пользователю, для возможного опроса в будущем
sqlite3.OperationalError: near ")": syntax error
2022-04-25 00:11:26,082 ERROR asyncio Task exception was never retrieved
future: <Task finished name='Task-76' coro=<Dispatcher._process_polling_updates() done, defined at C:\Users\Zakhar_M\AppData\Local\Programs\Python\Python38-32\lib\site-packages\aiogram\dispatcher\dispatcher.py:407> exception=TypeError("answer() missing 1 required positional argument: 'text'")>
Traceback (most recent call last):
  File "C:\Users\Zakhar_M\AppData\Local\Programs\Python\Python38-32\lib\site-packages\aiogram\dispatcher\dispatcher.py", line 415, in _process_polling_updates
    for responses in itertools.chain.from_iterable(await self.process_updates(updates, fast)):
  File "C:\Users\Zakhar_M\AppData\Local\Programs\Python\Python38-32\lib\site-packages\aiogram\dispatcher\dispatcher.py", line 235, in process_updates
    return await asyncio.gather(*tasks)
  File "C:\Users\Zakhar_M\AppData\Local\Programs\Python\Python38-32\lib\site-packages\aiogram\dispatcher\handler.py", line 116, in notify
    response = await handler_obj.handler(*args, **partial_data)
  File "C:\Users\Zakhar_M\AppData\Local\Programs\Python\Python38-32\lib\site-packages\aiogram\dispatcher\dispatcher.py", line 283, in process_update
    return await self.callback_query_handlers.notify(update.callback_query)
  File "C:\Users\Zakhar_M\AppData\Local\Programs\Python\Python38-32\lib\site-packages\aiogram\dispatcher\handler.py", line 116, in notify
    response = await handler_obj.handler(*args, **partial_data)
  File "F:/Zakhar/Python/FFFFFFFFFFFFFFF/FeDaZa_SCP_Tg_Database/q2.py", line 82, in callbacks_num
    await call.message.answer(reply_markup=markup_menu)
TypeError: answer() missing 1 required positional argument: 'text'
2022-04-25 00:11:50,776 ERROR aiogram.dispatcher.dispatcher Cause exception while getting updates.
Traceback (most recent call last):
  File "C:\Users\Zakhar_M\AppData\Local\Programs\Python\Python38-32\lib\site-packages\aiogram\dispatcher\dispatcher.py", line 381, in start_polling
    updates = await self.bot.get_updates(
  File "C:\Users\Zakhar_M\AppData\Local\Programs\Python\Python38-32\lib\site-packages\aiogram\bot\bot.py", line 110, in get_updates
    result = await self.request(api.Methods.GET_UPDATES, payload)
  File "C:\Users\Zakhar_M\AppData\Local\Programs\Python\Python38-32\lib\site-packages\aiogram\bot\base.py", line 231, in request
    return await api.make_request(await self.get_session(), self.server, self.__token, method, data, files,
  File "C:\Users\Zakhar_M\AppData\Local\Programs\Python\Python38-32\lib\site-packages\aiogram\bot\api.py", line 140, in make_request
    return check_result(method, response.content_type, response.status, await response.text())
  File "C:\Users\Zakhar_M\AppData\Local\Programs\Python\Python38-32\lib\site-packages\aiogram\bot\api.py", line 119, in check_result
    exceptions.ConflictError.detect(description)
  File "C:\Users\Zakhar_M\AppData\Local\Programs\Python\Python38-32\lib\site-packages\aiogram\utils\exceptions.py", line 140, in detect
    raise err(cls.text or description)
aiogram.utils.exceptions.TerminatedByOtherGetUpdates: Terminated by other getupdates request; make sure that only one bot instance is running
2022-04-25 00:14:28,479 ERROR root None
2022-04-25 00:14:28,480 ERROR asyncio Task exception was never retrieved
future: <Task finished name='Task-38' coro=<Dispatcher._process_polling_updates() done, defined at C:\Users\Zakhar_M\AppData\Local\Programs\Python\Python38-32\lib\site-packages\aiogram\dispatcher\dispatcher.py:407> exception=OperationalError('near ")": syntax error')>
Traceback (most recent call last):
  File "F:\Zakhar\Python\FFFFFFFFFFFFFFF\FeDaZa_SCP_Tg_Database\utilites.py", line 59, in browse
    print(browse[language])
KeyError: None

During handling of the above exception, another exception occurred:

Traceback (most recent call last):
  File "C:\Users\Zakhar_M\AppData\Local\Programs\Python\Python38-32\lib\site-packages\aiogram\dispatcher\dispatcher.py", line 415, in _process_polling_updates
    for responses in itertools.chain.from_iterable(await self.process_updates(updates, fast)):
  File "C:\Users\Zakhar_M\AppData\Local\Programs\Python\Python38-32\lib\site-packages\aiogram\dispatcher\dispatcher.py", line 235, in process_updates
    return await asyncio.gather(*tasks)
  File "C:\Users\Zakhar_M\AppData\Local\Programs\Python\Python38-32\lib\site-packages\aiogram\dispatcher\handler.py", line 116, in notify
    response = await handler_obj.handler(*args, **partial_data)
  File "C:\Users\Zakhar_M\AppData\Local\Programs\Python\Python38-32\lib\site-packages\aiogram\dispatcher\dispatcher.py", line 283, in process_update
    return await self.callback_query_handlers.notify(update.callback_query)
  File "C:\Users\Zakhar_M\AppData\Local\Programs\Python\Python38-32\lib\site-packages\aiogram\dispatcher\handler.py", line 116, in notify
    response = await handler_obj.handler(*args, **partial_data)
  File "F:/Zakhar/Python/FFFFFFFFFFFFFFF/FeDaZa_SCP_Tg_Database/q3.py", line 72, in callbacks_num
    info = browse(f'{int(num_SCP) + 1}', call.message.chat.id)
  File "F:\Zakhar\Python\FFFFFFFFFFFFFFF\FeDaZa_SCP_Tg_Database\utilites.py", line 78, in browse
    cur.execute(  # Фиксирование ошибки и прикрепление ошибки к пользователю, для возможного опроса в будущем
sqlite3.OperationalError: near ")": syntax error
2022-04-25 00:15:08,309 ERROR root None
2022-04-25 00:15:08,309 ERROR asyncio Task exception was never retrieved
future: <Task finished name='Task-42' coro=<Dispatcher._process_polling_updates() done, defined at C:\Users\Zakhar_M\AppData\Local\Programs\Python\Python38-32\lib\site-packages\aiogram\dispatcher\dispatcher.py:407> exception=OperationalError('near ")": syntax error')>
Traceback (most recent call last):
  File "F:\Zakhar\Python\FFFFFFFFFFFFFFF\FeDaZa_SCP_Tg_Database\utilites.py", line 59, in browse
    print(browse[language])
KeyError: None

During handling of the above exception, another exception occurred:

Traceback (most recent call last):
  File "C:\Users\Zakhar_M\AppData\Local\Programs\Python\Python38-32\lib\site-packages\aiogram\dispatcher\dispatcher.py", line 415, in _process_polling_updates
    for responses in itertools.chain.from_iterable(await self.process_updates(updates, fast)):
  File "C:\Users\Zakhar_M\AppData\Local\Programs\Python\Python38-32\lib\site-packages\aiogram\dispatcher\dispatcher.py", line 235, in process_updates
    return await asyncio.gather(*tasks)
  File "C:\Users\Zakhar_M\AppData\Local\Programs\Python\Python38-32\lib\site-packages\aiogram\dispatcher\handler.py", line 116, in notify
    response = await handler_obj.handler(*args, **partial_data)
  File "C:\Users\Zakhar_M\AppData\Local\Programs\Python\Python38-32\lib\site-packages\aiogram\dispatcher\dispatcher.py", line 283, in process_update
    return await self.callback_query_handlers.notify(update.callback_query)
  File "C:\Users\Zakhar_M\AppData\Local\Programs\Python\Python38-32\lib\site-packages\aiogram\dispatcher\handler.py", line 116, in notify
    response = await handler_obj.handler(*args, **partial_data)
  File "F:/Zakhar/Python/FFFFFFFFFFFFFFF/FeDaZa_SCP_Tg_Database/q3.py", line 72, in callbacks_num
    info = browse(f'{int(num_SCP) + 1}', call.message.chat.id)
  File "F:\Zakhar\Python\FFFFFFFFFFFFFFF\FeDaZa_SCP_Tg_Database\utilites.py", line 78, in browse
    cur.execute(  # Фиксирование ошибки и прикрепление ошибки к пользователю, для возможного опроса в будущем
sqlite3.OperationalError: near ")": syntax error
2022-04-25 06:01:40,831 ERROR aiogram.dispatcher.dispatcher Cause exception while getting updates.
Traceback (most recent call last):
  File "C:\Users\Zakhar_M\AppData\Local\Programs\Python\Python38-32\lib\site-packages\aiogram\dispatcher\dispatcher.py", line 381, in start_polling
    updates = await self.bot.get_updates(
  File "C:\Users\Zakhar_M\AppData\Local\Programs\Python\Python38-32\lib\site-packages\aiogram\bot\bot.py", line 110, in get_updates
    result = await self.request(api.Methods.GET_UPDATES, payload)
  File "C:\Users\Zakhar_M\AppData\Local\Programs\Python\Python38-32\lib\site-packages\aiogram\bot\base.py", line 231, in request
    return await api.make_request(await self.get_session(), self.server, self.__token, method, data, files,
  File "C:\Users\Zakhar_M\AppData\Local\Programs\Python\Python38-32\lib\site-packages\aiogram\bot\api.py", line 139, in make_request
    async with session.post(url, data=req, **kwargs) as response:
  File "C:\Users\Zakhar_M\AppData\Local\Programs\Python\Python38-32\lib\site-packages\aiohttp\client.py", line 1138, in __aenter__
    self._resp = await self._coro
  File "C:\Users\Zakhar_M\AppData\Local\Programs\Python\Python38-32\lib\site-packages\aiohttp\client.py", line 559, in _request
    await resp.start(conn)
  File "C:\Users\Zakhar_M\AppData\Local\Programs\Python\Python38-32\lib\site-packages\aiohttp\client_reqrep.py", line 913, in start
    self._continue = None
  File "C:\Users\Zakhar_M\AppData\Local\Programs\Python\Python38-32\lib\site-packages\aiohttp\helpers.py", line 721, in __exit__
    raise asyncio.TimeoutError from None
asyncio.exceptions.TimeoutError
2022-04-26 20:43:21,651 ERROR aiogram.dispatcher.dispatcher Cause exception while getting updates.
Traceback (most recent call last):
  File "C:\Users\Acer\AppData\Local\Programs\Python\Python310\lib\site-packages\aiogram\dispatcher\dispatcher.py", line 381, in start_polling
    updates = await self.bot.get_updates(
  File "C:\Users\Acer\AppData\Local\Programs\Python\Python310\lib\site-packages\aiogram\bot\bot.py", line 110, in get_updates
    result = await self.request(api.Methods.GET_UPDATES, payload)
  File "C:\Users\Acer\AppData\Local\Programs\Python\Python310\lib\site-packages\aiogram\bot\base.py", line 231, in request
    return await api.make_request(await self.get_session(), self.server, self.__token, method, data, files,
  File "C:\Users\Acer\AppData\Local\Programs\Python\Python310\lib\site-packages\aiogram\bot\api.py", line 140, in make_request
    return check_result(method, response.content_type, response.status, await response.text())
  File "C:\Users\Acer\AppData\Local\Programs\Python\Python310\lib\site-packages\aiogram\bot\api.py", line 119, in check_result
    exceptions.ConflictError.detect(description)
  File "C:\Users\Acer\AppData\Local\Programs\Python\Python310\lib\site-packages\aiogram\utils\exceptions.py", line 140, in detect
    raise err(cls.text or description)
aiogram.utils.exceptions.TerminatedByOtherGetUpdates: Terminated by other getupdates request; make sure that only one bot instance is running
