2022-04-17 22:15:50,135 ERROR asyncio Task exception was never retrieved
future: <Task finished name='Task-7' coro=<Dispatcher._process_polling_updates() done, defined at C:\Users\Acer\AppData\Local\Programs\Python\Python310\lib\site-packages\aiogram\dispatcher\dispatcher.py:407> exception=IndexError('list index out of range')>
Traceback (most recent call last):
  File "C:\Users\Acer\AppData\Local\Programs\Python\Python310\lib\site-packages\aiogram\dispatcher\dispatcher.py", line 415, in _process_polling_updates
    for responses in itertools.chain.from_iterable(await self.process_updates(updates, fast)):
  File "C:\Users\Acer\AppData\Local\Programs\Python\Python310\lib\site-packages\aiogram\dispatcher\dispatcher.py", line 235, in process_updates
    return await asyncio.gather(*tasks)
  File "C:\Users\Acer\AppData\Local\Programs\Python\Python310\lib\site-packages\aiogram\dispatcher\handler.py", line 116, in notify
    response = await handler_obj.handler(*args, **partial_data)
  File "C:\Users\Acer\AppData\Local\Programs\Python\Python310\lib\site-packages\aiogram\dispatcher\dispatcher.py", line 256, in process_update
    return await self.message_handlers.notify(update.message)
  File "C:\Users\Acer\AppData\Local\Programs\Python\Python310\lib\site-packages\aiogram\dispatcher\handler.py", line 116, in notify
    response = await handler_obj.handler(*args, **partial_data)
  File "C:\Users\Acer\PycharmProjects\FeDaZa_SCP_Tg_Database\main.py", line 66, in profile
    await bot.send_photo(msg.chat.id, str(profile[0][7]))
IndexError: list index out of range
